Workbook
Name Slicer_NetworkType: #N/A
Name Slicer_Region: #N/A

Sheet Raw Data
A1: TowerID | B1: Region | C1: NetworkType | D1: SignalStrength_dBm | E1: DataUsage_GB | F1: CallDropRate_Percent | G1: Latency_ms | H1: Uptime_Percent | I1: Downtime_Hours | J1: ActiveUsers | K1: Date | L1: Signal_Status
A2: TWR001 | B2: Nairobi | C2: 5G | D2: -65 | E2: 850 | F2: 1.2 | G2: 20 | H2: 99.8 | I2: 2 | J2: 1200 | K2: 46023 | L2: =IF(D2>-75,"Strong",IF(D2>-90,"Moderate","Weak")) -> Strong | M2: Weak Towers | N2: =COUNTIF(L:L,"Weak") -> 2
A3: TWR002 | B3: Mombasa | C3: 4G | D3: -78 | E3: 430 | F3: 3.5 | G3: 45 | H3: 98.7 | I3: 10 | J3: 850 | K3: 46024 | L3: =IF(D3>-75,"Strong",IF(D3>-90,"Moderate","Weak")) -> Moderate | M3: Strong Towers | N3: =COUNTIF(L:L,"Strong") -> 10
A4: TWR003 | B4: Kisumu | C4: 5G | D4: -60 | E4: 920 | F4: 0.8 | G4: 18 | H4: 99.9 | I4: 1 | J4: 1400 | K4: 46025 | L4: =IF(D4>-75,"Strong",IF(D4>-90,"Moderate","Weak")) -> Strong | M4: Moderate Towers | N4: =COUNTIF(L:L,"Moderate") -> 8
A5: TWR004 | B5: Nakuru | C5: 4G | D5: -82 | E5: 390 | F5: 4.2 | G5: 55 | H5: 97.5 | I5: 18 | J5: 700 | K5: 46026 | L5: =IF(D5>-75,"Strong",IF(D5>-90,"Moderate","Weak")) -> Moderate
A6: TWR005 | B6: Eldoret | C6: 5G | D6: -70 | E6: 610 | F6: 2 | G6: 30 | H6: 99 | I6: 5 | J6: 980 | K6: 46027 | L6: =IF(D6>-75,"Strong",IF(D6>-90,"Moderate","Weak")) -> Strong | M6: Weak Tower Data Usage | N6: =SUMIF(L:L,"Weak",E:E) -> 470
A7: TWR006 | B7: Thika | C7: 4G | D7: -88 | E7: 300 | F7: 5.1 | G7: 70 | H7: 96.8 | I7: 25 | J7: 500 | K7: 46028 | L7: =IF(D7>-75,"Strong",IF(D7>-90,"Moderate","Weak")) -> Moderate | M7: Strong Tower Data Usage | N7: =SUMIF(L:L,"Strong",E:E) -> 9160
A8: TWR007 | B8: Nairobi | C8: 5G | D8: -58 | E8: 1100 | F8: 0.5 | G8: 15 | H8: 99.9 | I8: 1 | J8: 1700 | K8: 46029 | L8: =IF(D8>-75,"Strong",IF(D8>-90,"Moderate","Weak")) -> Strong | M8: Moderate Tower Data Usage | N8: =SUMIF(L:L,"Moderate",E:E) -> 3120
A9: TWR008 | B9: Mombasa | C9: 4G | D9: -75 | E9: 470 | F9: 3 | G9: 40 | H9: 98.2 | I9: 12 | J9: 780 | K9: 46030 | L9: =IF(D9>-75,"Strong",IF(D9>-90,"Moderate","Weak")) -> Moderate
A10: TWR009 | B10: Kisumu | C10: 5G | D10: -62 | E10: 980 | F10: 1 | G10: 22 | H10: 99.7 | I10: 3 | J10: 1500 | K10: 46031 | L10: =IF(D10>-75,"Strong",IF(D10>-90,"Moderate","Weak")) -> Strong
A11: TWR010 | B11: Nakuru | C11: 4G | D11: -85 | E11: 350 | F11: 4.8 | G11: 60 | H11: 97 | I11: 20 | J11: 620 | K11: 46032 | L11: =IF(D11>-75,"Strong",IF(D11>-90,"Moderate","Weak")) -> Moderate
A12: TWR011 | B12: Eldoret | C12: 5G | D12: -68 | E12: 720 | F12: 1.5 | G12: 28 | H12: 99.3 | I12: 4 | J12: 1050 | K12: 46033 | L12: =IF(D12>-75,"Strong",IF(D12>-90,"Moderate","Weak")) -> Strong
A13: TWR012 | B13: Thika | C13: 4G | D13: -90 | E13: 250 | F13: 6 | G13: 80 | H13: 95.5 | I13: 30 | J13: 430 | K13: 46034 | L13: =IF(D13>-75,"Strong",IF(D13>-90,"Moderate","Weak")) -> Weak
A14: TWR013 | B14: Nairobi | C14: 5G | D14: -55 | E14: 1250 | F14: 0.3 | G14: 12 | H14: 99.95 | I14: 0.5 | J14: 2000 | K14: 46035 | L14: =IF(D14>-75,"Strong",IF(D14>-90,"Moderate","Weak")) -> Strong
A15: TWR014 | B15: Mombasa | C15: 4G | D15: -80 | E15: 410 | F15: 3.8 | G15: 50 | H15: 97.8 | I15: 15 | J15: 720 | K15: 46036 | L15: =IF(D15>-75,"Strong",IF(D15>-90,"Moderate","Weak")) -> Moderate
A16: TWR015 | B16: Kisumu | C16: 5G | D16: -64 | E16: 870 | F16: 1.1 | G16: 25 | H16: 99.5 | I16: 2 | J16: 1320 | K16: 46037 | L16: =IF(D16>-75,"Strong",IF(D16>-90,"Moderate","Weak")) -> Strong
A17: TWR016 | B17: Nakuru | C17: 4G | D17: -87 | E17: 320 | F17: 5.3 | G17: 68 | H17: 96.5 | I17: 26 | J17: 540 | K17: 46038 | L17: =IF(D17>-75,"Strong",IF(D17>-90,"Moderate","Weak")) -> Moderate
A18: TWR017 | B18: Eldoret | C18: 5G | D18: -69 | E18: 680 | F18: 1.7 | G18: 32 | H18: 99.1 | I18: 5 | J18: 990 | K18: 46039 | L18: =IF(D18>-75,"Strong",IF(D18>-90,"Moderate","Weak")) -> Strong
A19: TWR018 | B19: Thika | C19: 4G | D19: -92 | E19: 220 | F19: 6.5 | G19: 90 | H19: 94.8 | I19: 35 | J19: 390 | K19: 46040 | L19: =IF(D19>-75,"Strong",IF(D19>-90,"Moderate","Weak")) -> Weak
A20: TWR019 | B20: Nairobi | C20: 5G | D20: -57 | E20: 1180 | F20: 0.4 | G20: 14 | H20: 99.92 | I20: 1 | J20: 1850 | K20: 46041 | L20: =IF(D20>-75,"Strong",IF(D20>-90,"Moderate","Weak")) -> Strong
A21: TWR020 | B21: Mombasa | C21: 4G | D21: -79 | E21: 450 | F21: 3.2 | G21: 42 | H21: 98.5 | I21: 11 | J21: 810 | K21: 46042 | L21: =IF(D21>-75,"Strong",IF(D21>-90,"Moderate","Weak")) -> Moderate

Sheet Tower Search
B2: Enter Tower ID | C2: TWR009
B3: Region | C3: =VLOOKUP(C2,'Raw Data'!A:K,2,FALSE) -> Kisumu
B4: Network Type | C4: =VLOOKUP(C2,'Raw Data'!A:K,3,FALSE) -> 5G

Sheet Pivot Analysis
A1: Row Labels | B1: Sum of DataUsage_GB
A2: Nairobi | B2: 4380
A3: Kisumu | B3: 2770
A4: Eldoret | B4: 2010
A5: Mombasa | B5: 1760
A6: Nakuru | B6: 1060
A7: Thika | B7: 770
A8: Grand Total | B8: 12750
B9: =SUM(B2:B7) -> 12750
A11: Row Labels | B11: Average of SignalStrength_dBm
A12: Nairobi | B12: -58.75
A13: Kisumu | B13: -62
A14: Eldoret | B14: -69
A15: Mombasa | B15: -78
A16: Nakuru | B16: -84.666667
A17: Thika | B17: -90
A18: Grand Total | B18: -73.2
B19: =AVERAGE(B12:B17) -> -73.736111
A21: Row Labels | B21: Sum of ActiveUsers
A22: Nairobi | B22: 6750
A23: Kisumu | B23: 4220
A24: Mombasa | B24: 3160
A25: Eldoret | B25: 3020
A26: Nakuru | B26: 1860
A27: Thika | B27: 1320
A28: Grand Total | B28: 20330
B29: =SUM(B22:B27) -> 20330
A31: Row Labels | B31: Average of Downtime_Hours
A32: TWR018 | B32: 35
A33: TWR012 | B33: 30
A34: TWR016 | B34: 26
A35: TWR006 | B35: 25
A36: TWR010 | B36: 20
A37: TWR004 | B37: 18
A38: TWR014 | B38: 15
A39: TWR008 | B39: 12
A40: TWR020 | B40: 11
A41: TWR002 | B41: 10
A42: TWR005 | B42: 5
A43: TWR017 | B43: 5
...

Sheet Dashboard
B1: Telecom Network Performance Dashboard
A5: Total Active Users | E5: Total Data Usage | I5: Avg Signal Strength | M5: Avg Downtime
A6: ='Pivot Analysis'!B29 -> 20330 | E6: ='Pivot Analysis'!B9 -> 12750 | F6: GB | I6: ='Pivot Analysis'!B19 -> -73.736111 | J6: dBm | M6: ='Pivot Analysis'!B53 -> 11.325 | N6: hrs
B44: Key Telecom Insights
B45: • Nairobi region records highest data usage
B46: • Some weak-signal towers still handle heavy traffic
B47: • Downtime varies significantly across regions
B48: • 5G towers show increased user activity
